# 有异常的错误处理

在这最后一章中，我们将学习如何在系统编程时执行错误处理。具体来说，将提出三种不同的方法。第一种方法将演示如何使用 POSIX 样式的错误处理，而第二种方法将演示如何使用标准的 C-style set 跳转异常。第三种方法将演示如何使用 C ++ 异常，并讨论每种方法的优缺点。最后，本章将以一个示例作为结尾，该示例演示 C 异常如何优于 POSIX 风格的错误处理。

在本章中，我们将介绍以下主题:

*   POSIX 风格的错误处理
*   C 中的异常支持
*   带有异常基准的示例

# 技术要求

为了编译和执行本章中的示例，读者必须具有以下内容:

*   能够编译和执行 C 17 的基于 Linux 的系统 (例如，Ubuntu 17.10)
*   GCC 7
*   C 让 3.6
*   互联网连接

要下载本章中的所有代码，包括示例和代码片段，请参见以下链接: [https://github.com/PacktPublishing/ 动手系统编程与 CPP/tree/master/Chapter13](https://github.com/PacktPublishing/Hands-On-System-Programming-with-CPP/tree/master/Chapter13)。

# 错误处理 POSIX 样式

POSIX 风格的错误处理提供了最基本的错误处理形式，能够在几乎任何系统，几乎任何程序中利用。考虑到标准 C，POSIX 风格的错误处理采用以下形式:

```cpp
if (foo() != 0) {
    std::cout << errno << '\n';
}
```

通常，调用的每个函数要么在`success`上返回`0`，要么在`-1`失败时返回`-1`，并将错误代码存储到全局 (非线程安全) 实现定义的宏，称为`errno`。`0`用于`success`的原因是，在大多数 cpu 上，将变量与`0`进行比较比将变量与任何其他值进行比较要快，并且`success`情况是预期的情况。下面的示例演示了如何使用此模式:

```cpp
#include <cstring>
#include <iostream>

int myfunc(int val)
{
    if (val == 42) {
        errno = EINVAL;
        return -1;
    }

    return 0;
}

int main()
{
    if (myfunc(1) == 0) {
        std::cout << "success\n";
    }
    else {
        std::cout << "failure: " << strerror(errno) << '\n';
    }

    if (myfunc(42) == 0) {
        std::cout << "success\n";
    }
    else {
        std::cout << "failure: " << strerror(errno) << '\n';
    }
}

// > g++ -std=c++17 scratchpad.cpp; ./a.out
// success
// failure: Invalid argument
```

在这个例子中，我们创建了一个名为`myfunc()`的函数，它取一个整数并返回一个整数。该函数接受任何值作为其参数为*有效*，除了`42`。如果将`42`作为输入函数提供，则该函数返回`-1`并将`errno`设置为`EINVAL`，这说明该函数提供了一个无效的参数。

在`main`函数中，我们调用`myfunc()`，既有有效的输入，又有无效的输入和测试，以查看是否发生错误，导致有效的输入为`success`，无效的输入为`failure: Invalid argument`。应该注意的是，我们利用`strerror()`函数，该函数将 POSIX 定义的错误代码转换为它们的字符串等价物。还应该注意的是，在我们对其进行构建和改进的过程中，整个本章都将利用这个简单的示例。

从这个简单的例子中产生的第一个问题是，函数的输出是错误处理的杠杆，但是如果函数需要输出一个错误代码以外的值怎么办？有两种方法可以解决这个问题。处理此问题的第一种方法是约束函数的有效输出 (即，并非所有输出都被视为有效)。这通常是 POSIX 处理此问题的方式。下面的示例演示了这一点:

```cpp
#include <cstring>
#include <iostream>

int myfunc(int val)
{
    if (val == 42) {
        errno = EINVAL;
        return 0;
    }

    return 42;
}

int main()
{
    if (auto handle = myfunc(1); handle != 0) {
        std::cout << "success: " << handle << '\n';
    }
    else {
        std::cout << "failure: " << strerror(errno) << '\n';
    }

    if (auto handle = myfunc(42); handle != 0) {
        std::cout << "success: " << handle << '\n';
    }
    else {
        std::cout << "failure: " << strerror(errno) << '\n';
    }
}

// > g++ -std=c++17 scratchpad.cpp; ./a.out
// success: 42
// failure: Invalid argument
```

在前面的示例中，我们创建了一个`myfunc()`函数，该函数返回给定的有效输入`handle`和给定的无效输入`0`。这类似于许多返回文件句柄的 POSIX 函数。在这种情况下，`success`的概念是相反的，此外，句柄可能永远不会采用`0`的值，因为这是用来表示错误的。提供错误处理同时还提供函数输出的另一种可能的方法是返回多个值，如下所示:

```cpp
#include <utility>
#include <cstring>
#include <iostream>

std::pair<int, bool>
myfunc(int val)
{
    if (val == 42) {
        errno = EINVAL;
        return {0, false};
    }

    return {42, true};
}

int main()
{
    if (auto [handle, success] = myfunc(1); success) {
        std::cout << "success: " << handle << '\n';
    }
    else {
        std::cout << "failure: " << strerror(errno) << '\n';
    }

    if (auto [handle, success] = myfunc(42); success) {
        std::cout << "success: " << handle << '\n';
    }
    else {
        std::cout << "failure: " << strerror(errno) << '\n';
    }
}

// > g++ -std=c++17 scratchpad.cpp; ./a.out
// success: 42
// failure: Invalid argument
```

在前面的示例中，我们返回`std::pair{}` (实际上只是一个具有两个值的结构)。对中的第一个值是我们的句柄，而我们对中的第二个值确定句柄是否有效。使用这种机制，`0`可能是一个有效的句柄，因为我们有一种方法可以告诉这个函数的用户它是否有效。另一种方法是为函数提供一个参数，该参数充当*输出*而不是*输入*，这是 C 核心准则所不鼓励的做法。这通过以下代码来描述:

```cpp
#include <cstring>
#include <iostream>

int myfunc(int val, int &error)
{
    if (val == 42) {
        error = EINVAL;
        return 0;
    }

    return 42;
}

int main()
{
    int error = 0;

    if (auto handle = myfunc(1, error); error == 0) {
        std::cout << "success: " << handle << '\n';
    }
    else {
        std::cout << "failure: " << strerror(error) << '\n';
    }

    if (auto handle = myfunc(42, error); error == 0) {
        std::cout << "success: " << handle << '\n';
    }
    else {
        std::cout << "failure: " << strerror(error) << '\n';
    }
}

// > g++ -std=c++17 scratchpad.cpp; ./a.out
// success: 42
// failure: Invalid argument
```

在这个例子中，`myfunc()`采用两个参数，第二个参数接受一个用来存储错误的整数。如果错误整数保持在`0`，则没有发生错误。但是，如果设置了错误整数，则会发生错误，我们会检测到该错误并输出故障。尽管 C 核心指南不鼓励这种方法 (主要是因为有更好的方法在 C 中执行错误处理)，但这种方法还有一个额外的好处，即错误整数是线程安全的，不像使用`errno`，它不是线程安全的。

除了 POSIX 样式错误处理的冗长性和错误值被忽略的趋势之外，POSIX 样式错误处理的最大问题是许多分支语句，这些分支语句必须在不太可能发生错误的情况下连续执行。下面的示例演示了这一点:

```cpp
#include <cstring>
#include <iostream>

int myfunc(int val)
{
    if (val == 42) {
        errno = EINVAL;
        return -1;
    }

    return 0;
}

int nested1(int val)
{
    if (auto ret = myfunc(val); ret != 0) {
        std::cout << "nested1 failure: " << strerror(errno) << '\n';
        return ret;
    }
    else {
        std::cout << "nested1 success\n";
    }

    return 0;
}

int nested2(int val)
{
    if (auto ret = nested1(val); ret != 0) {
        std::cout << "nested2 failure: " << strerror(errno) << '\n';
        return ret;
    }
    else {
        std::cout << "nested2 success\n";
    }

    return 0;
}

int main()
{
    if (nested2(1) == 0) {
        std::cout << "nested2(1) complete\n";
    }
    else {
        std::cout << "nested2(1) failure: " << strerror(errno) << '\n';
    }

    if (nested2(42) == 0) {
        std::cout << "nested2(42) complete\n";
    }
    else {
        std::cout << "nested2(42) complete: " << strerror(errno) << '\n';
    }
}

// > g++ -std=c++17 scratchpad.cpp; ./a.out
// nested1 success
// nested2 success
// nested2(1) complete
// nested1 failure: Invalid argument
// nested2 failure: Invalid argument
// nested2(42) failure: Invalid argument
```

在此示例中，我们创建了相同的`myfunc()`函数，如果提供的输入为`42`，则返回错误。然后，我们从另一个函数调用的函数中调用这个函数 (也就是说，我们正在对我们的`myfunc()`进行嵌套调用，这是在系统编程时很可能发生的一种做法)。由于`myfunc()`可能会返回错误，并且我们的嵌套函数无法处理该错误，因此它们还必须返回错误代码，而该错误代码又必须进行检查。本示例中的大部分代码仅提供错误处理逻辑，旨在将错误的结果转发给下一个函数，以希望下一个函数能够处理错误。

此嵌套错误转发可以称为`stack unwinding`。每次调用可能返回错误的函数时，我们都会检查是否发生了错误，并将结果返回到堆栈中的下一个函数。这个展开调用堆栈的过程会重复进行，直到我们找到调用堆栈中能够处理错误的函数。在我们的例子中，这是`main()`函数。

POSIX 风格的错误处理的问题是必须手动执行堆栈展开，因此，此代码在`success`情况下是连续执行的，从而导致性能不佳的冗长代码，如前面的示例所示，该代码仅在三个嵌套调用中检查一个简单的整数值。

最后需要注意的是，POSIX 风格的错误处理确实支持**资源获取是初始化** (**RAII**)，含义在函数的作用域中定义的对象被正确销毁该函数在`success`情况和错误情况下都退出，如下面的示例所示:

```cpp
#include <cstring>
#include <iostream>

class myclass
{
public:
    ~myclass()
    {
        std::cout << "destructor called\n";
    }
};

int myfunc(int val)
{
    myclass c{};

    if (val == 42) {
        errno = EINVAL;
        return -1;
    }

    return 0;
}

int main()
{
    if (myfunc(1) == 0) {
        std::cout << "success\n";
    }
    else {
        std::cout << "failure: " << strerror(errno) << '\n';
    }

    if (myfunc(42) == 0) {
        std::cout << "success\n";
    }
    else {
        std::cout << "failure: " << strerror(errno) << '\n';
    }
}

// > g++ -std=c++17 scratchpad.cpp; ./a.out
// destructor called
// success
// destructor called
// failure: Invalid argument
```

在上面的示例中，我们创建了一个简单的类，该类在销毁时将字符串输出到`stdout`，并在我们的`myfunc()`函数中创建一个该类的实例。当调用`myfunc()`时，无论是在`success`上还是在失败上，类的析构函数都在退出时被正确调用。在我们的下一个错误处理机制中，称为 set jump，我们将演示如何解决 POSIX 样式错误处理的许多问题，同时还演示 set jump 的关键限制是缺乏 RAII 支持，可能导致未定义的行为。

# 学习设置跳转异常

Set jump 异常可能被视为 C 风格异常。与 C 风格的异常一样，set jump exception 为用户提供了在出现错误的情况下在代码中设置返回位置的能力，以及生成执行跳转的异常的方法。下面的代码示例演示了这一点:

```cpp
#include <cstring>
#include <csetjmp>

#include <iostream>

std::jmp_buf jb;

void myfunc(int val)
{
    if (val == 42) {
        errno = EINVAL;   // Invalid argument
        std::longjmp(jb, -42);
    }
}

int main()
{
    if (setjmp(jb) == -42) {
        std::cout << "failure: " << strerror(errno) << '\n';
        std::exit(EXIT_FAILURE);
    }

    myfunc(1);
    std::cout << "success\n";

    myfunc(42);
    std::cout << "success\n";
}

// > g++ -std=c++17 scratchpad.cpp; ./a.out
// success
// failure: Invalid argument
```

在这个例子中，我们创建了我们的`myfunc()`函数，但是我们没有返回错误代码，而是执行了一个跳远，它的作用就像*goto*，跳到调用堆栈中最后一个调用`setjmp()`的地方。在我们的`main`函数中，我们首先调用`setjmp()`放置我们的返回点，然后我们调用我们的`myfunc()`函数，同时输入一个有效的输入和一个无效的输入。

立即，我们解决了 POSIX 风格错误处理的几个问题。从前面的示例中可以看出，代码的复杂性要小得多，因此无需检查错误条件。此外，`myfunc()`返回一个 void，因为不需要返回错误代码，这意味着不再需要约束函数的输出来支持错误情况，从下面的示例中可以看出:

```cpp
#include <cstring>
#include <csetjmp>

#include <iostream>

std::jmp_buf jb;

int myfunc(int val)
{
    if (val == 42) {
        errno = EINVAL;
        std::longjmp(jb, -1);
    }

    return 42;
}

int main()
{
    if (setjmp(jb) == -1) {
        std::cout << "failure: " << strerror(errno) << '\n';
        std::exit(EXIT_FAILURE);
    }

    auto handle1 = myfunc(1);
    std::cout << "success: " << handle1 << '\n';

    auto handle2 = myfunc(42);
    std::cout << "success: " << handle2 << '\n';
}

// > g++ -std=c++17 scratchpad.cpp; ./a.out
// success: 42
// failure: Invalid argument
```

在本示例中，`myfunc()`返回一个*句柄*，错误情况使用设置跳转异常处理。结果，`myfunc()`可能返回任何值，并且函数的用户根据是否调用了跳远知道句柄是否有效。

由于不再需要`myfunc()`的返回值，我们也不再需要检查`myfunc()`的返回值，这意味着我们的嵌套示例大大简化了，如下所示:

```cpp
#include <cstring>
#include <csetjmp>

#include <iostream>

std::jmp_buf jb;

void myfunc(int val)
{
    if (val == 42) {
        errno = EINVAL;
        std::longjmp(jb, -1);
    }
}

void nested1(int val)
{
    myfunc(val);
    std::cout << "nested1 success\n";
}

void nested2(int val)
{
    nested1(val);
    std::cout << "nested2 success\n";
}

int main()
{
    if (setjmp(jb) == -1) {
        std::cout << "failure: " << strerror(errno) << '\n';
        exit(EXIT_FAILURE);
    }

    nested2(1);
    std::cout << "nested2(1) complete\n";

    nested2(42);
    std::cout << "nested2(42) complete\n";
}

// > g++ -std=c++17 scratchpad.cpp; ./a.out
// nested1 success
// nested2 success
// nested2(1) complete
// failure: Invalid argument
```

可以看出，本示例中唯一的错误逻辑存在于`myfunc()`检查中，以确保输入有效。剩余的错误逻辑已被移除。这不仅导致代码更易于阅读和维护，而且生成的代码也表现得更好，因为我们不再执行分支语句，而是手工解卷调用堆栈。

使用设置跳转异常的另一个好处是可以创建线程安全的错误处理。在我们前面的示例中，我们在出现错误的情况下设置`errno`，然后在到达能够处理错误的代码时读取该错误。使用 set jump，不再需要`errno`，因为我们可以使用以下方法返回跳远本身的错误代码:

```cpp
#include <cstring>
#include <csetjmp>

#include <iostream>

void myfunc(int val, jmp_buf &jb)
{
    if (val == 42) {
        std::longjmp(jb, EINVAL);
    }
}

int main()
{
    std::jmp_buf jb;

    if (auto ret = setjmp(jb); ret > 0) {
        std::cout << "failure: " << strerror(ret) << '\n';
        std::exit(EXIT_FAILURE);
    }

    myfunc(1, jb);
    std::cout << "success\n";

    myfunc(42, jb);
    std::cout << "success\n";
}

// > g++ -std=c++17 scratchpad.cpp; ./a.out
// success
// failure: Invalid argument
```

在前面的示例中，我们不是在跳远中设置`errno`并返回`-1`，而是在跳远中返回错误代码，并且使用 C 17 语法，将跳远的值存储在我们的调用中，以设置跳转，并确保该值大于`0`。第一次设置跳转被调用，它返回`0`，因为还没有发生错误，这意味着分支没有被取。但是，如果第二次调用 set jump (当调用我们的跳远时)，则返回在对我们的跳远调用中放置的值，从而导致采用分支并以线程安全的方式报告错误。

请注意，我们需要对示例进行的唯一修改是，我们必须传递每个函数的跳转缓冲区，这非常不方便，尤其是在嵌套函数调用的情况下。在我们之前的示例中，跳转缓冲区是全局存储的，这不是线程安全的，但是更方便，并且可以产生更干净的代码。

除了提供线程安全的尴尬机制外，使用 set 跳转进行错误处理的主要缺点是缺乏对 RAII 的支持，这意味着在函数范围内创建的对象可能没有在退出时调用其析构函数 (实际上是特定于实现的问题)。不调用析构函数的原因是该函数从技术上永远不会退出。set jump/long jump 在调用 set jump 时将指令指针和非易失性寄存器存储在跳转缓冲区中。

当执行跳转时，应用程序会用存储在跳转缓冲区中的值覆盖指令指针和 CPU 寄存器，然后继续执行，就好像调用`setjump()`之后的代码从未执行过一样。因此，对象的析构函数永远不会执行，如下面的示例所示:

```cpp
#include <cstring>
#include <csetjmp>

#include <iostream>

jmp_buf jb;

class myclass
{
public:
    ~myclass()
    {
        std::cout << "destructor called\n";
    }
};

void myfunc(int val)
{
    myclass c{};

    if (val == 42) {
        errno = EINVAL;
        std::longjmp(jb, -1);
    }
}

int main()
{
    if (setjmp(jb) == -1) {
        std::cout << "failure: " << strerror(errno) << '\n';
        exit(EXIT_FAILURE);
    }

    myfunc(1);
    std::cout << "success\n";

    myfunc(42);
    std::cout << "success\n";
}

// > g++ -std=c++17 scratchpad.cpp; ./a.out
// destructor called
// success
// failure: Invalid argument
```

在这个例子中，我们创建一个简单的类，当类被销毁时，它将字符串输出到`stdout`。然后，我们在`myfunc()`中创建一个该类的实例。在`success`情况下，析构函数被调用为`myfunc()`退出，导致析构函数被调用。但是，在失败的情况下，`myfunc()`永远不会退出，导致析构函数没有被调用。

在下一节中，我们将讨论基于 set jump 异常构建的 C 异常，不仅提供对 RAII 的支持，而且还提供在出现错误时返回复杂数据类型的能力。

# 理解 C ++ 中的异常支持

C 异常提供了一种以线程安全的方式报告错误的机制，而无需手动解除调用堆栈，同时还提供了对 RAII 和复杂数据类型的支持。为了更好地理解这一点，请参考以下示例:

```cpp
#include <cstring>
#include <iostream>

void myfunc(int val)
{
    if (val == 42) {
        throw EINVAL;
    }
}

int main()
{
    try {
        myfunc(1);
        std::cout << "success\n";

        myfunc(42);
        std::cout << "success\n";
    }
    catch(int ret) {
        std::cout << "failure: " << strerror(ret) << '\n';
    }
}

// > g++ -std=c++17 scratchpad.cpp; ./a.out
// success
// failure: Invalid argument
```

在前面的例子中，我们的`myfunc()`函数与它的 POSIX 风格的等效函数相比已经大大简化了。就像我们前面的示例一样，如果提供给函数的输入是`42`，则返回错误 (在这种情况下，实际上是抛出的)。如果提供的输入不是`42`，则函数返回成功。

像设置跳转一样，对`myfunc()`的调用不再需要检查函数的返回值，因为没有提供返回值。为了处理错误情况，我们将调用包装到`myfunc()`在`try...catch`块中。如果`try{}`块中的任何一个代码导致引发异常，则将执行`catch[}`块。与大多数 C 一样，`catch`块是类型安全的，这意味着您必须说明在引发异常的情况下计划接收哪种类型的返回数据。在这种情况下，我们抛出`EINVAL`，这是一个整数，因此我们捕获一个整数并将结果输出到`stdout`。

与 set jump 类似，`myfunc()`不再需要返回错误代码，这意味着它可以自由输出它想要的任何值 (意味着输出不受约束)，如下一个示例所示:

```cpp
#include <cstring>
#include <iostream>

int myfunc(int val)
{
    if (val == 42) {
        throw EINVAL;
    }

    return 42;
}

int main()
{
    try {
       auto handle1 = myfunc(1);
        std::cout << "success: " << handle1 << '\n';

        auto handle2 = myfunc(42);
        std::cout << "success: " << handle2 << '\n';
    }
    catch(int ret) {
        std::cout << "failure: " << strerror(ret) << '\n';
    }
}

// > g++ -std=c++17 scratchpad.cpp; ./a.out
// success: 42
// failure: Invalid argument
```

在前面的示例中，`myfunc()`返回一个句柄，该句柄可能具有任何值，因为如果抛出异常，此函数的用户将知道该句柄是否有效。

与 set jump 类似，与 POSIX 风格的错误处理示例相比，我们的嵌套情况大大简化了，因为我们不再需要手动取消调用堆栈:

```cpp
#include <cstring>
#include <iostream>
void myfunc(int val)
{
    if (val == 42) {
        throw EINVAL;
    }
}

void nested1(int val)
{
    myfunc(val);
    std::cout << "nested1 success\n";
}

void nested2(int val)
{
    nested1(val);
    std::cout << "nested2 success\n";
}

main()
{
    try {
        nested2(1);
        std::cout << "nested2(1) complete\n";

        nested2(42);
        std::cout << "nested2(42) complete\n";
    }
    catch(int ret) {
        std::cout << "failure: " << strerror(ret) << '\n';
    }
}

// > g++ -std=c++17 scratchpad.cpp; ./a.out
// nested1 success
// nested2 success
// nested2(1) complete
// failure: Invalid argument
```

前面的示例类似于我们的 set jump 示例，主要区别在于我们抛出异常而不是执行跳远，并且我们使用`try...catch`块捕获异常。

与设置跳转不同，C 异常支持 RAII，这意味着在函数退出时，在函数范围内定义的反对被正确销毁:

```cpp
#include <cstring>
#include <iostream>

class myclass
{
public:
    ~myclass()
    {
        std::cout << "destructor called\n";
    }
};

void myfunc(int val)
{
    myclass c{};

    if (val == 42) {
        throw EINVAL;
    }
}

main()
{
    try {
        myfunc(1);
        std::cout << "success\n";

        myfunc(42);
        std::cout << "success\n";
    }
    catch(int ret) {
        std::cout << "failure: " << strerror(ret) << '\n';
    }
}

// > g++ -std=c++17 scratchpad.cpp; ./a.out
// destructor called
// success
// destructor called
// failure: Invalid argument
```

从前面的示例中可以看出，在`success`情况和失败情况下都调用了析构函数。为了实现这一点，C 包含一个堆栈解卷器，它能够自动解卷堆栈，类似于我们如何使用 POSIX 风格的错误处理手动解卷调用堆栈，但自动且不需要通过代码执行分支语句，导致最佳性能 (好像没有进行错误检查)。这称为**零开销异常处理**。

关于解卷机如何自动解卷调用堆栈而不产生任何性能开销，同时仍然以线程安全的方式支持 RAII 的细节不在本书的范围之内，因为这个过程非常复杂。然而，下面有一个简短的解释。

当启用 C 异常并编译您的代码时，还会为每个函数编译一组堆栈展开指令，并将可执行文件放置在 C 异常展开器可以找到它们的地方。然后，编译器编译代码，就好像没有发生错误处理一样，代码也这样执行。如果引发异常，则会创建一个线程安全的对象，该对象包装要引发的数据并进行存储。从那里，使用以前保存在可执行文件中的调用堆栈展开指令来反转函数的执行，最终导致将异常抛出的函数退出到其调用者。在函数退出之前，将执行所有析构函数，并且对于在调用堆栈中调用的每个函数继续此过程，直到遇到能够处理抛出的数据的`catch{}`块。

以下是一些要记住的关键点:

*   展开指令存储在可执行文件的表中。每次需要反转函数的执行时 (从寄存器的角度来看)，解卷机必须在表中查找下一个函数的这些指令。这个操作很慢 (尽管已经添加了一些优化，包括使用哈希表)。因此，不应该将异常用于控制流，因为它们在错误情况下是缓慢且低效的，而在`success`情况下则非常有效。C 异常应仅用于错误处理。
*   您在程序中拥有的功能越多，或者功能越大 (也就是说，该功能接触 cpu 寄存器的越多)，必须存储在展开指令表中的信息就越多，从而导致更大的程序。如果您的程序中从未使用过 C 异常，则此信息仍将被编译并存储在应用程序中。因此，如果不使用异常，则应禁用异常。

除了具有线程安全，性能和支持 RAII 的能力外，C 异常都支持复杂的数据类型。C 使用的典型数据类型包括字符串，如下所示:

```cpp
#include <cstring>
#include <iostream>

void myfunc(int val)
{
    if (val == 42) {
        throw std::runtime_error("invalid val");
    }
}

int main()
{
    try {
        myfunc(1);
        std::cout << "success\n";

        myfunc(42);
        std::cout << "success\n";
    }
    catch(const std::runtime_error &e) {
        std::cout << "failure: " << e.what() << '\n';
    }
}

// > g++ -std=c++17 scratchpad.cpp; ./a.out
// success
// failure: invalid val
```

在前面的例子中，我们抛出一个`std::runtime_error{}`异常。此异常是由 C 提供的继承`std::exception`的众多异常之一，它支持除了异常类型本身之外还存储字符串的能力。在前面的示例中，我们存储`invalid val`。前面的代码不仅能够检测提供的字符串，还能够检测出`std::runtime_exception{}`被抛出的事实。

在某些情况下，您可能不知道抛出的异常类型。当抛出不继承`std::exception`的异常 (如原始字符串和整数) 时，通常会出现这种情况。要捕获任何异常，请使用以下内容:

```cpp
#include <cstring>
#include <iostream>

void myfunc(int val)
{
    if (val == 42) {
        throw -1;
    }
}

main()
{
    try {
        myfunc(1);
        std::cout << "success\n";

        myfunc(42);
        std::cout << "success\n";
    }
    catch(...) {
        std::cout << "failure\n";
    }
}

// > g++ -std=c++17 scratchpad.cpp; ./a.out
// success
// failure
```

在前面的示例中，我们抛出一个整数，然后使用`...`语法捕获它，该语法指出我们希望捕获所有异常。最好的做法是至少在代码中的某个地方使用这种类型的 catch 语句，以确保所有异常都被捕获。在本书的所有示例中，出于这个原因，我们都包含了这个`catch`语句。这种类型的`catch{}`块的主要缺点是我们必须使用`std::current_exception()`来获取异常，例如:

```cpp
#include <cstring>
#include <iostream>
#include <stdexcept>

void myfunc1(int val)
{
    if (val == 42) {
        throw std::runtime_error("runtime_error");
    }
}

void myfunc2(int val)
{
    try {
        myfunc1(val);
    }
    catch(...) {
        auto e = std::current_exception();
        std::rethrow_exception(e);
    }
}

int main()
{
    try {
        myfunc2(42);
    }
    catch(const std::exception& e) {
        std::cout << "caught: " << e.what() << '\n';
    }
}

// > g++ -std=c++17 scratchpad.cpp; ./a.out
// caught: runtime_error
```

在前面的示例中，我们从`myfunc1()`抛出`std::runtime_error()`。在`myfunc2()`中，我们使用`...`语法捕获异常，表示我们希望捕获所有异常。要获取异常，我们必须使用`std::current_exception()`，它返回`std::exception_ptr{}`。`std::exception_ptr{}`是一种实现特定的指针类型，可以使用`std::rethrow_exception()`重新抛出。使用此函数，然后我们可以使用前面的标准方法捕获异常，并在其中输出消息。需要注意的是，如果你想捕捉一个异常，`std::current_exception()`不是推荐的方式，因为你需要重新抛出异常来获取它的`what()`，因为`std::exception_ptr`不提供获取`what()`的接口。还应注意，如果抛出的异常不是`std::exception{}`的子类，则`std::current_exception()`将无济于事。

最后，可以用您自己的自定义数据替换`subclass std::exception`。为此，请参考以下示例:

```cpp
#include <cstring>
#include <iostream>
#include <stdexcept>

class myexception : public std::exception
{
    int m_error{0};

public:

    myexception(int error) noexcept :
        m_error{error}
    { }

    const char *
    what() const noexcept
    {
      return "error";
    }

    int error() const noexcept
    {
        return m_error;
    }
};

void myfunc(int val)
{
    if (val == 42) {
        throw myexception(42);
    }
}

int main()
{
    try {
        myfunc(1);
        std::cout << "success\n";

        myfunc(42);
        std::cout << "success\n";
    }
    catch(const myexception &e) {
        std::cout << "failure: " << std::to_string(e.error()) << '\n';
    }
}

// > g++ -std=c++17 scratchpad.cpp; ./a.out
// success
// failure: 42
```

在前面的示例中，我们对`std::exception`进行子类化以创建自己的异常，该异常能够存储错误号。与`std::exception{}`的所有子类一样，`what()`函数应该重载，以提供唯一标识您的自定义异常的消息。在我们的例子中，我们还提供了一个函数来检索创建和抛出异常时存储的错误代码。

另一个常见的任务是为您的异常创建一个自定义字符串。但是，这可能会导致一个常见的错误，即在`what()`函数中返回一个构造的字符串:

```cpp
const char *
what() const noexcept
{
    return ("error: " + std::to_string(m_error)).c_str();
}
```

前面的代码产生了未定义的行为，并且很难找到错误。在前面的代码中，我们像在前面的示例中一样存储错误代码，但是我们没有返回它，而是在`what()`函数中以字符串返回错误代码。为此，我们利用`std::to_string()`函数将错误代码转换为`std::string`。然后，我们将 `error:` 放在前面，并返回结果的标准 C 字符串。

前面示例的问题是，返回一个指向标准 C 字符串的指针，然后在 `what()` 函数退出时销毁`std::string{}`。尝试使用此函数返回的字符串的代码将最终读取已删除的内存。很难找到的原因是，在某些情况下，此代码将按预期执行，只是因为内存的内容可能变化不够快。但是，如果有足够的时间，此代码可能会导致腐败。

相反，要创建输出相同消息的字符串，请将生成的错误代码放在现有异常的构造函数中:

```cpp
#include <cstring>
#include <iostream>

class myexception : public std::runtime_error
{
public:
    myexception(int error) noexcept :
        std::runtime_error("error: " + std::to_string(42))
    { }
};

void myfunc(int val)
{
    if (val == 42) {
        throw myexception(42);
    }
}

int main()
{
    try {
        myfunc(1);
        std::cout << "success\n";

        myfunc(42);
        std::cout << "success\n";
    }
    catch(const std::exception &e) {
        std::cout << "failure: " << e.what() << '\n';
    }
}

// > g++ -std=c++17 scratchpad.cpp; ./a.out
// success
// failure: error: 42
```

在前面的示例中，我们直接对`std::runtime_error{}`进行子类化，而不是`std::exception`，并在构造异常期间创建`what()`消息。这样，当调用`what()`时，异常信息可用而不会损坏。

在本章结束时，我们将以注释说明关于例外支持的唯一实际添加到 C 17。通常不鼓励在已经抛出异常时抛出异常。要完成此操作，您必须从已标记为`except()`的类的析构函数中抛出一个异常，该异常在堆栈展开过程中被销毁。在 C 17 之前，析构函数可以通过利用`std::uncaught_exception()`函数来检测是否即将发生这种情况，如果抛出异常，该函数将返回 true。为了支持在已经抛出异常时抛出异常，C 17 将此函数更改为返回一个整数，该整数表示当前抛出的异常总数:

```cpp
#include <cstring>
#include <iostream>

class myclass
{
public:
    ~myclass()
    {
        std::cout << "uncaught_exceptions: "
                  << std::uncaught_exceptions() << '\n';
    }
};

void myfunc(int val)
{
    myclass c{};

    if (val == 42) {
        throw EINVAL;
    }
}

int main()
{
    try {
        myfunc(1);
        std::cout << "success\n";

        myfunc(42);
        std::cout << "success\n";
    }
    catch(int ret) {
        std::cout << "failure: " << strerror(ret) << '\n';
    }
}

// > g++ -std=c++17 scratchpad.cpp; ./a.out
// uncaught_exceptions: 0
// success
// uncaught_exceptions: 1
// failure: Invalid argument
```

在前面的示例中，我们创建了一个类，该类输出为当前抛出的异常总数`stdout`。然后在`myfunc()`中实例化这个类。在成功的情况下，当类被销毁时，没有异常被抛出。在错误情况下，一个异常报告为在类被销毁时抛出。

# 研究异常基准示例

在最后一个例子中，我们将证明 C 异常优于 POSIX 风格的异常 (这种说法在很大程度上取决于您正在执行的硬件，因为编译器优化和积极的分支预测可以提高 POSIX 风格的错误处理的性能)。

POSIX 风格的错误处理要求用户在每次执行函数时检查其结果。当函数嵌套发生时 (几乎肯定会发生)，这个问题会进一步加剧。在这个例子中，我们将把这种情况发挥到极致，创建一个递归函数，它检查自己的结果几千次，同时执行测试几十万次。每个测试都将进行基准测试，并将结果进行比较。

有很多因素可能会改变此测试的结果，包括分支预测，优化和操作系统。这项测试的目标是将这个例子发挥到极致，以至于这些问题中的大多数都在噪音中被冲刷掉，任何方法的任何性能相关问题都很容易识别。

首先，我们需要以下内容:

```cpp
#include <csetjmp>

#include <chrono>
#include <iostream>

```

我们还将需要以下全局定义的跳转缓冲区，因为我们将比较 C 异常来设置跳转和 POSIX 风格的错误处理:

```cpp
jmp_buf jb;
```

我们还将使用我们在前面的章节中使用的相同的基准代码:

```cpp
template<typename FUNC>
auto benchmark(FUNC func) {
    auto stime = std::chrono::high_resolution_clock::now();
    func();
    auto etime = std::chrono::high_resolution_clock::now();

    return (etime - stime).count();
}
```

我们的第一个递归函数将使用 POSIX 风格的错误处理返回错误:

```cpp
int myfunc1(int val)
{
    if (val >= 0x10000000) {
        return -1;
    }

    if (val < 0x1000) {
        if (auto ret = myfunc1(val + 1); ret == -1) {
            return ret;
        }
    }

    return 0;
}
```

如图所示，将函数的返回值按预期进行比较。第二个函数将使用设置跳转返回错误:

```cpp
void myfunc2(int val)
{
    if (val >= 0x10000000) {
        std::longjmp(jb, -1);
    }

    if (val < 0x1000) {
        myfunc2(val + 1);
    }
}
```

正如预期的那样，此功能不太复杂，因为不需要返回或比较返回值。最后，第三个函数将使用 C ++ 异常返回一个错误:

```cpp
void myfunc3(int val)
{
    if (val >= 0x10000000) {
        throw -1;
    }

    if (val < 0x1000) {
        myfunc3(val + 1);
    }
}
```

正如预期的那样，此功能几乎与 set jump 相同，唯一的区别是使用 C 异常。由于我们没有测试 RAII，因此我们希望 C 异常的执行速度与设置跳转一样快，因为两者都不需要执行比较。

最后，在我们受保护的`main`函数中，我们将按照前面示例中的相同方式执行每个函数，以演示每个函数均按预期执行:

```cpp
void test_func1()
{
    if (auto ret = myfunc1(0); ret == 0) {
        std::cout << "myfunc1: success\n";
    }
    else {
        std::cout << "myfunc1: failure\n";
    }

    if (auto ret = myfunc1(bad); ret == 0) {
        std::cout << "myfunc1: success\n";
    }
    else {
        std::cout << "myfunc1: failure\n";
    }

    uint64_t total = 0;
    for (auto i = 0; i < num_iterations; i++) {
        total += benchmark([&] {
            myfunc1(0);
        });
    }

    std::cout << "time1: " << total << '\n';
}
```

第一个测试函数测试 C 风格的错误处理逻辑，以确保函数按预期返回成功和失败。然后，我们执行成功案例几次，并花费多长时间执行，将结果输出到`stdout`:

```cpp
void test_func2()
{
    if (setjmp(jb) == -1) {
        std::cout << "myfunc2: failure\n";

        uint64_t total = 0;
        for (auto i = 0; i < num_iterations; i++) {
            total += benchmark([&] {
                myfunc2(0);
            });
        }

        std::cout << "time2: " << total << '\n';
        return;
    }

    myfunc2(0);
    std::cout << "myfunc2: success\n";

    myfunc2(bad);
    std::cout << "myfunc2: success\n";
}
```

如图所示，我们还确保第二个 C 风格的异常示例也按预期返回成功和失败。然后，我们执行成功案例几次，看看执行需要多长时间:

```cpp
void test_func3()
{
    try {
        myfunc3(0);
        std::cout << "myfunc3: success\n";

        myfunc3(bad);
        std::cout << "myfunc3: success\n";
    }
    catch(...) {
        std::cout << "myfunc3: failure\n";
    }

    uint64_t total = 0;
    for (auto i = 0; i < num_iterations; i++) {
        total += benchmark([&] {
            myfunc3(0);
        });
    }

    std::cout << "time3: " << total << '\n';
}
```

我们用我们的 C 例外示例做同样的事情。我们通过执行每个测试来完成我们的`protected_main()`功能，如下所示:

```cpp
int
protected_main(int argc, char** argv)
{
    (void) argc;
    (void) argv;

    test_func1();
    test_func2();
    test_func3();

    return EXIT_SUCCESS;
}
```

基准测试结果输出到`stdout`:

```cpp
int
main(int argc, char **argv)
{
    try {
        return protected_main(argc, argv);
    }
    catch (const std::exception &e) {
        std::cerr << "Caught unhandled exception:\n";
        std::cerr << " - what(): " << e.what() << '\n';
    }
    catch (...) {
        std::cerr << "Caught unknown exception\n";
    }

    return EXIT_FAILURE;
}
```

与我们所有的示例一样，`protected_main()`函数由`main()`函数执行，该函数会捕获异常。

# 编译和测试

为了编译此代码，我们利用了我们一直在其他示例中使用的相同的`CMakeLists.txt`文件: [https://github.com/PacktPublishing/ 使用 CPP/blob/master/Chapter13/CMakeLists.txt](https://github.com/PacktPublishing/Hands-On-System-Programming-with-CPP/blob/master/Chapter13/CMakeLists.txt)。

有了这一点，我们可以使用以下内容编译此代码:

```cpp
> git clone https://github.com/PacktPublishing/Hands-On-System-Programming-with-CPP.git
> cd Hands-On-System-Programming-with-CPP/Chapter13/
> mkdir build
> cd build

> cmake ..
> make
```

要执行该示例，请运行以下代码:

```cpp
> ./example1
myfunc1: success
myfunc1: failure
time1: 1750637978
myfunc2: success
myfunc2: failure
time2: 1609691756
myfunc3: success
myfunc3: failure
time3: 1593301696
```

如前面的代码片段所示，C 异常优于 POSIX 样式的错误处理，并且 set 跳转异常具有可比性。

# 摘要

在本章中，我们学习了在系统编程时执行错误处理的三种不同方法。第一种方法是 POSIX 风格的错误处理，它涉及从执行的每个函数返回错误代码，并检查每个函数的结果以检测错误。第二种方法涉及使用标准 C 风格的异常 (即设置跳转)，演示了这种形式的异常处理如何解决 POSIX 风格的错误处理的许多问题，但引入了 RAII 支持和线程安全的问题。第三个例子讨论了使用 C ++ 异常进行错误处理，以及这种形式的错误处理如何解决本章讨论的大多数问题，唯一的缺点是增加了生成的可执行文件的大小。最后，本章以一个示例作为结尾，该示例演示了 C 异常如何优于 POSIX 风格的错误处理。

# 问题

1.  为什么 C 异常优于 POSIX 风格的错误处理？
2.  函数如何返回具有 POSIX 风格错误处理的输出？
3.  为什么不设置跳转支持 RAII？
4.  如何使用`catch{}`块捕获任何异常？
5.  为什么 C 异常会增加可执行文件的大小？
6.  为什么控制流不应该使用 C 异常？

# 进一步阅读

*   [https://www.packtpub.com/application-development/c17-example](https://www.packtpub.com/application-development/c17-example)
*   [https://www.packtpub.com/application-development/getting-started-c17-programming-video](https://www.packtpub.com/application-development/getting-started-c17-programming-video)