# *第 11 章*: 处理异常

本章将开始我们的任务，将您的 C 编程库扩展到 OOP 概念之外，目的是使您能够编写更健壮和可扩展的代码。我们将从探索 C++ 中的异常处理开始这项工作。在我们的代码中添加语言规定的方法来处理错误将使我们能够实现更少的错误和更可靠的程序。通过使用语言内置的形式化异常处理机制*，我们可以实现对错误的统一处理，从而使代码更容易维护。*

在本章中，我们将介绍以下主要主题:

*   了解异常处理基础知识-`try`、`throw`和`catch`
*   探索异常处理机制-尝试使用几种变体来引发异常，引发 (抛出)，捕获和处理异常的代码
*   使用具有标准异常对象的异常层次结构或通过创建自定义的异常类

在本章结束时，您将了解如何在 C 中使用异常处理。您将看到如何识别错误以引发异常，通过抛出异常将程序的控制权转移到指定区域，然后通过捕获异常并希望修复手头的问题来处理错误。

您还将学习如何利用 C 标准库中的标准异常，以及如何创建自定义的异常对象。可以设计异常类的层次结构，以添加强大的错误检测和处理功能。

让我们通过探索异常处理的内置语言机制来扩展编程库，从而增加对 C 的理解。

# 技术要求

完整程序示例的在线代码可以在以下 GitHub URL 上找到: [https://github.com/PacktPublishing/ Demystified-Object-Oriented-Programming-带有-CPP/blob/master/Chapter11](https://github.com/PacktPublishing/Demystified-Object-Oriented-Programming-with-CPP/blob/master/Chapter11)。每个完整的程序示例都可以在 GitHub 存储库中找到相应的章节标题 (子目录) 下的文件，该文件与章节编号相对应，然后是破折号，然后是手头章节中的示例编号。例如，本章中的第一个完整程序可以在上述 GitHub 目录下的一个名为`Chp11-Ex1.cpp`的文件中的子目录`Chapter11`中找到。

本章的中央情报局视频可以在: [https://bit.ly/3r8LHd5](https://bit.ly/3r8LHd5)观看。

# 理解异常处理

应用程序中可能会发生错误情况，从而阻止程序正确地继续进行。这种错误条件可能包括超过应用程序限制的数据值、不可用的必要输入文件或数据库、耗尽的堆内存或任何其他可想象的问题。C 异常提供了一种统一的，语言支持的方式来处理程序异常。

在引入语言支持的异常处理机制之前，每个程序员都会以自己的方式处理错误，有时根本不会。未处理的程序错误和异常意味着在应用程序的某个地方，会发生意外结果，并且应用程序通常会异常终止。这些潜在的结果肯定是不可取的!

C**异常处理**提供了一种语言支持的机制来检测和纠正程序异常，以便应用程序可以保持运行状态，而不是突然结束。

让我们看一下机制，从语言支持的关键字`try`，`throw`和`catch`开始，它们包括 C中的异常处理。

## 利用异常处理与 try、throw 和 catch

**异常处理**检测程序异常，如程序员或类库所定义的，并将控制权传递给可能处理特定问题的应用程序的另一部分。只有作为最后手段，才有必要退出应用程序。

让我们先看看支持异常处理的关键字。关键词是:

*   `try`: 允许程序员*尝试*可能导致异常的部分代码。
*   `throw`: 一旦发现错误，`throw`将引发异常。这将导致跳转到关联的 try 块下方的 catch 块。Throw 将允许将参数返回到关联的 catch 块。抛出的参数可以是任何标准或用户定义的类型。
*   `catch`: 指定一个代码块，旨在寻找已引发的异常，以尝试纠正这种情况。同一作用域中的每个 catch 块将处理不同类型的异常。

在使用异常处理时，回顾回溯的想法很有用。当一系列函数被调用时，我们在堆栈上建立适用于每个连续函数调用的状态信息 (参数、局部变量和返回值空间)，以及每个函数的返回地址。当引发异常时，我们可能需要将堆栈展开到函数调用 (或 try 块) 序列开始的始发点，同时重置堆栈指针。这个过程被称为**回溯**，它允许程序返回到代码中的较早序列。回溯不仅适用于函数调用，还适用于包括嵌套尝试块在内的嵌套块。

下面是一个简单的示例来说明基本的异常处理语法和用法。尽管未显示代码的某些部分以节省空间，但完整的示例可以在我们的 GitHub 中找到，如下所示:

[https://github.com/PacktPublishing/Demystified-Object-Oriented-Programming-with-CPP/blob/master/Chapter11/Chp11-Ex1.cpp](https://github.com/PacktPublishing/Demystified-Object-Oriented-Programming-with-CPP/blob/master/Chapter11/Chp11-Ex1.cpp)

```cpp
// Assume Student class is as we've seen before, but with one
// additional virtual member function. Assume usual headers.
void Student::Validate()  // defined as virtual in class def
{                         // so derived classes may override
    // check constructed Student to see if standards are met
    // if not, throw an exception
    throw "Does not meet prerequisites";
}
int main()
{
    Student s1("Sara", "Lin", 'B', "Dr.", 3.9,"C++", "23PSU");
    try    // Let's 'try' this block of code -- 
    {      // Validate() may raise an exception
        s1.Validate();  // does s1 meet admission standards?
    }
    catch (const char *err)
    {
        cout << err << endl;
        // try to fix problem here…
        exit(1); // only if you can't fix, exit gracefully
    } 
    cout << "Moving onward with remainder of code." << endl;
    return 0;
}
```

在前面的代码片段中，我们可以看到关键字`try`，`throw`和`catch`在操作。首先，让我们注意一下`Student::Validate()`成员函数。想象一下，在这种虚拟方法中，我们验证了`Student`符合录取标准。如果是这样，则功能正常结束。如果没有，则会引发异常。在此示例中，将抛出一个简单的`const char *`，其中包含消息 “`Does not meet prerequisites`”。

在我们的`main()`函数中，我们首先实例化一个`Student`，即`s1`。然后，我们将呼叫嵌套到 try 块内的`s1.Validate()`。我们从字面上说，我们想尝试*这个代码块。应该`Student::Validate()`按预期工作，没有错误，我们的程序完成 try 块，跳过 try 块下方的 catch 块，并且仅继续任何 catch 块下方的代码。*

但是，如果`Student::Validate()`抛出一个异常，我们将跳过我们的 try 块中的任何剩余代码，并在随后定义的 catch 块中寻找与`const char *`类型匹配的异常。在这里，在匹配的 catch 块中，我们的目标是尽可能纠正错误。如果我们成功了，我们的程序将继续使用 catcher 下方的代码。如果没有，我们的工作就是优雅地结束程序。

让我们看一下上述程序的输出:

```cpp
Student does not meet prerequisites 
```

接下来，我们用以下物流总结异常处理的总体流程:

*   当程序完成 try 块而没有遇到任何抛出的异常时，代码序列将继续执行 catch 块后面的语句。一个 try 块可能遵循多个 catch 块 (具有不同的参数类型)。
*   当引发异常时，程序必须回溯并返回到包含始发函数调用的 try 块。程序可能必须回溯过去的多个功能。当回溯发生时，堆栈上遇到的对象将被弹出，从而被破坏。
*   一旦程序 (引发异常) 回溯到执行 try 块的函数，程序将继续 catch 块 (在 try 块之后)，其签名与抛出的异常类型匹配。
*   类型转换 (通过公共继承相关的向上投射对象除外) 将无法匹配潜在的 catch 块。但是，具有椭圆 (`…`) 的捕获块可以用作最通用的捕获块类型，并且可以捕获任何类型的异常。
*   如果不存在匹配的`catch`块，程序将从 C 标准库调用`terminate()`。请注意，`terminate()`将调用`abort()`，但是，程序员可以通过`set_terminate()`函数为`terminate()`注册另一个函数来调用。

现在，让我们看看如何用`set_terminate()`注册函数。虽然我们在这里只显示了代码的关键部分，但完整的程序可以在我们的 GitHub 中找到:

[https://github.com/PacktPublishing/Demystified-Object-Oriented-Programming-with-CPP/blob/master/Chapter11/Chp11-Ex2.cpp](https://github.com/PacktPublishing/Demystified-Object-Oriented-Programming-with-CPP/blob/master/Chapter11/Chp11-Ex2.cpp)

```cpp
void AppSpecificTerminate()
{   // first, do what is necessary to end program gracefully
    cout << "Uncaught exception. Program terminating" << endl;
    exit(1);
}
int main()
{   
    set_terminate(AppSpecificTerminate);  // register fn.
    return 0;
}
```

在前面的代码片段中，我们定义了自己的`AppSpecificTerminate()`函数。这是我们希望有`terminate()`函数调用的函数，而不是它调用`abort()`的默认行为。也许我们使用`AppSpecificTerminate()`来更优雅地结束我们的应用程序，保存关键数据结构或数据库值。当然，我们也会自己`exit()` (或`abort()`)。

在`main()`中，我们仅仅调用`set_terminate(AppSpecificTerminate)`来注册我们的`terminate`函数和`set_terminate()`。现在，当以其他方式调用`abort()`时，我们的函数将被调用。

有趣的是，`set_terminate()`返回一个指向先前安装的`terminate_handler`的函数指针 (第一次调用该指针将是指向`abort()`的指针)。如果我们选择保存此值，则可以使用它来恢复先前注册的终止处理程序。请注意，在本示例中，我们没有选择保存此函数指针。

以下是使用上述代码的未捕获异常的输出外观:

```cpp
Uncaught exception. Program terminating
```

请记住，诸如`terminate()`、`abort()`和`set_terminate()`之类的函数来自标准库。尽管我们可以使用范围解析运算符 (例如`std::terminate()`) 在它们的名称之前加上库名称，但这不是必需的。

注

异常处理并不是要代替简单的程序员错误检查; 异常处理具有更大的开销。应保留异常处理，以便以统一的方式并在通用位置处理更严重的编程错误。

现在我们已经看到了异常处理的基本机制，让我们来看看稍微复杂一点的异常处理示例。

## 探索具有典型变化的异常处理机制

异常处理可以比以前说明的基本机制更加复杂和灵活。让我们看一下异常处理基础知识的各种组合和变体，因为每种组合都可能适用于不同的编程情况。

### 将异常传递给外部处理程序

捕获的异常可能会传递给外部处理程序进行处理。或者，可以部分处理异常，然后将异常抛出到外部作用域以进行进一步处理。

让我们在前面的例子的基础上来演示这个原理。完整的程序可以在以下 GitHub 位置看到:

[https://github.com/PacktPublishing/Demystified-Object-Oriented-Programming-with-CPP/blob/master/Chapter11/Chp11-Ex3.cpp](https://github.com/PacktPublishing/Demystified-Object-Oriented-Programming-with-CPP/blob/master/Chapter11/Chp11-Ex3.cpp)

```cpp
// Assume Student class is as we've seen it before, but with
// two additional member functions. Assume usual header files.
void Student::Validate()  // defined as virtual in class def
{                         // so derived classes may override
    // check constructed student to see if standards are met
    // if not, throw an exception
    throw "Does not meet prerequisites";
}
bool Student::TakePrerequisites()  
{
    // Assume this function can correct the issue at hand
    // if not, it returns false
    return false;
}
int main()
{
    Student s1("Alex", "Ren", 'Z', "Dr.", 3.9, "C++", "89CU");
    try    // illustrates a nested try block 
    {   
        // Assume another important task occurred in this
        // scope, which may have also raised an exception
        try
        {   
            s1.Validate();  // may raise an exception
        }
        catch (const char *err)
        {
            cout << err << endl;
            // try to correct (or partially handle) error.
            // If you cannot, pass exception to outer scope
            if (!s1.TakePrerequisites())
                throw;    // re-throw the exception
        }
    }
    catch (const char *err) // outer scope catcher (handler)
    {
        cout << err << endl;
        // try to fix problem here…
        exit(1); // only if you can't fix, exit gracefully
    } 
    cout << "Moving onward with remainder of code. " << endl;
    return 0;
}
```

在前面提到的代码中，假设我们包含了通常的头文件，并定义了`Student`的通常类定义。现在，我们将通过添加`Student::Validate()`方法 (虚拟的，这样它可能会被覆盖) 和`Student::TakePrerequisites()`方法 (不是虚拟的，后代应该按需使用) 来增强`Student`类。

请注意，我们的`Student::Validate()`方法会引发一个异常，该异常只是一个字符串文字，其中包含指示当前问题的消息。我们可以想象，`Student::TakePrerequisites()` 方法的完整 i实现验证了 `Student` 满足了适当的前提条件，并相应地返回一个布尔值`true`或`false`。

在我们的`main()`函数中，我们现在注意到一组嵌套的 try 块。这里的目的是说明可能调用方法的内部 try 块，例如`s1.Validate()`，该方法可能引发异常。请注意，与内部 try 块相同的级别处理程序会捕获此异常。理想的情况是，在与它源自的 try 块相等的级别上处理异常，因此，假设在此范围内的捕捉器尝试这样做。例如，我们的 innermost catch 块大概会尝试纠正错误，并使用对`s1.TakePrerequisites()`的调用来测试是否已进行了纠正。

但是也许这个捕手只能部分处理异常。也许有一种知识，即外部级别的处理程序知道如何进行其余的校正。在这种情况下，可以将此异常重新抛出到外部 (嵌套) 级别。我们在最里面的 catch 块中的简单`throw;`语句就是这样做的。请注意，在外层有一个捕手。如果抛出的异常匹配，按类型划分，这个外部级别现在将有机会进一步处理异常，并希望纠正问题，以便应用程序可以继续。仅当此外部捕获块无法纠正错误时，才应退出应用程序。在我们的示例中，每个 catcher 都会打印出表示错误消息的字符串; 因此，此消息在输出中出现两次。

让我们看一下上述程序的输出:

```cpp
Student does not meet prerequisites
Student does not meet prerequisites
```

现在我们已经看到了如何使用嵌套的尝试和捕获块，让我们继续前进，看看如何将各种抛出类型和各种捕获块一起使用。

### 添加各种处理程序

有时，可能会从内部范围引发各种异常，从而为各种数据类型创建处理程序的必要性。异常处理程序 (即 catch 块) 可以接收任何数据类型的异常。通过使用具有基类类型的 catch 块，我们可以最大程度地减少引入的 catcher 的数量; 我们知道派生类对象 (通过公共继承相关) 可以始终向上转换为其基类类型。我们还可以在 catch 块中使用椭圆 (`…`) 来捕获以前未指定的任何内容。

让我们以我们最初的例子为基础，来说明各种各样的处理程序。尽管缩写，但我们的完整程序示例可以在我们的 GitHub 中找到，如下所示:

[https://github.com/PacktPublishing/Demystified-Object-Oriented-Programming-with-CPP/blob/master/Chapter11/Chp11-Ex4.cpp](https://github.com/PacktPublishing/Demystified-Object-Oriented-Programming-with-CPP/blob/master/Chapter11/Chp11-Ex4.cpp)

```cpp
// Assume Student class is as we've seen before, but with one
// additional virtual member function, Graduate(). Assume 
// a simple Course class exists. All headers are as usual.
void Student::Graduate()
{   // Assume the below if statements are fully implemented 
    if (gpa < 2.0) // if gpa doesn't meet requirements
        throw gpa;
    // if Student is short credits, throw how many are missing
        throw numCreditsMissing;  // assume this is an int
    // or if Student is missing a Course, construct and
    // then throw the missing Course as a referenceable object
    // Assume appropriate Course constructor exists
        throw *(new Course("Intro. To Programming", 1234)); 
    // or if another issue, throw a diagnostic message
        throw ("Does not meet requirements"); 
}
int main()
{
    Student s1("Ling", "Mau", 'I', "Ms.", 3.1, "C++", "55UD");
    try  
    {  
        s1.Graduate();
    }
    catch (float err)
    {
        cout << "Too low gpa: " << err << endl;
        exit(1); // only if you can't fix, exit gracefully
    } 
    catch (int err)
    {
        cout << "Missing " << err << " credits" << endl;
        exit(2);
    }
    catch (const Course &err)
    {
        cout << "Needs to take: " << err.GetTitle() << endl;
        cout << "Course #: " << err.GetCourseNum() << endl;
        // If you correct the error, and continue the program, 
        // be sure to deallocate heap mem using: delete &err;
        exit(3);  // Otherwise, heap memory for err will be 
    }             // reclaimed upon exit()
    catch (const char *err)
    {
        cout << err << endl;
        exit(4); 
    }
    catch (...)
    {
        cout << "Exiting" << endl;
        exit(5);
    }
    cout << "Moving onward with remainder of code." << endl;
    return 0;
}
```

在上述代码的段中，我们首先检查`Student::Graduate()`成员函数。在这里，我们可以想象这种方法贯穿了许多毕业要求，因此，可能会引发各种不同类型的异常。例如，如果`Student`实例的`gpa`太低，则会抛出一个 float 作为异常，表示学生的`gpa`较差。如果`Student`的学分太少，则会抛出一个整数，指示`Student`仍然需要多少学分才能获得学位。

也许最有趣的潜在错误`Student::Graduate()`可能是如果学生的毕业要求中缺少要求的`Course`。在这种情况下，`Student::Graduate()`将分配一个新的`Course`对象，并通过构造用`Course`名称和编号填充它。接下来，取消引用`Course`的指针，并通过引用抛出对象。然后，处理程序可以通过引用捕获此对象。

在`main()`函数中，我们仅将对`Student::Graduate()`的调用包装在 try 块中，因为此语句可能会引发异常。根据可能抛出的对象类型，catcher 序列遵循 try block-one`catch`语句。该序列中的最后一个捕获块使用椭圆 (`…`)，表示该捕获器将处理由`Student::Graduate()`引发的任何其他类型的异常，而其他捕获器尚未捕获。

实际接合的捕获块是使用`const Course &err`捕获`Course`的块。使用`const`限定符，我们可能不会修改处理程序中的`Course`，因此我们只能将`const`成员函数应用于此对象。

请注意，尽管上面显示的每个捕捉器仅打印出错误然后退出，但理想情况下，捕捉器会尝试纠正错误，以便应用程序不需要终止，从而允许捕获块下方的代码继续前进。

让我们看一下上述程序的输出:

```cpp
Needs to take: Intro. to Programming
Course #: 1234
```

现在我们已经看到了各种抛出的类型和各种捕获块，让我们继续前进，了解我们应该将 w组合在一起的单个尝试块。

### 将 try 块中的依赖项分组在一起

重要的是要记住，当 try 块中的一行代码遇到异常时，try 块的其余部分将被忽略。相反，程序继续使用匹配的 catcher (如果不存在合适的 catcher，则调用`terminate()`)。然后，如果修复了错误，则开始执行 “捕手” 之外的代码。请注意，我们永远不会返回以完成初始 try 块的其余部分。这种行为的含义是，您应该只将 try 块中的元素组合在一起。也就是说，如果一个项目导致异常，则完成该分组中的另一个项目不再重要。

请记住，捕手的目标是尽可能纠正错误。这意味着程序可以在适用的 catch 块之后继续前进。您可能会问: 在关联的 try 块中跳过一项现在可以接受吗？如果答案是否定的，那就重写你的代码。例如，您可能希望在`try`-`catch`分组周围添加一个循环，这样，如果捕获器纠正了错误，则从初始尝试块开始重试整个企业。

或者，进行较小的、连续的`try`-`catch`分组。也就是说，*尝试*在自己的尝试块中只有一个重要任务 (后面是适用的捕手)。然后*尝试*下一个任务在它自己的 try 块与其关联的捕手等。

接下来，让我们看一下在函数的原型中包含它可能引发的异常的类型的方法。

### 检查函数原型中的异常规范

我们可以选择通过扩展该函数的签名以包括可能引发的对象类型，来指定 C 函数可能引发的异常类型。但是，由于一个函数可能会抛出多种类型的异常 (或根本没有)，因此必须在运行时检查实际抛出的类型。因此，函数原型中的这些增强说明符也被称为**动态异常规范**。

让我们看一个例子，在一个函数的 ex倾向签名中使用异常类型:

```cpp
void Student::Graduate() throw(float, int, Course &, char *)
{
   // this method might throw any of the above mentioned types
}
void Student::Enroll() throw()
{
   // this method might throw any type of exception
}
```

在前面提到的代码片段中，我们看到了`Student`的两个成员函数。`Student::Graduate()`在其参数列表后包含`throw`关键字，然后作为此方法扩展签名的一部分，包含可能从该函数抛出的对象类型。请注意，在其扩展签名中，`Student::Enroll()`方法仅在`throw()`后面有一个空列表。这意味着`Student::Enroll()`可能会引发任何类型的异常。

在这两种情况下，通过将具有可选数据类型的关键字添加到签名中，我们提供了一种方法来向该函数的用户宣布可能抛出哪些类型的对象。然后，我们要求程序员在 try 块中包含对此方法的任何调用，然后再加上适当的捕手。

我们将看到，尽管扩展签名的想法似乎非常有帮助，但它在实践中有不利的问题。因此，动态异常规范已被弃用。因为您可能仍然会看到现有代码中使用的这些规范，包括标准库原型 (例如带有例外)，所以编译器仍然支持此已弃用的功能，并且您将需要了解它们的用法。

尽管动态异常 (如前所述的扩展函数签名) 已被弃用，但具有类似目的的说明符已添加到语言中，即`noexcept`关键字。可以在扩展签名之后添加此说明符，如下所示:

```cpp
void Student::Graduate() noexcept   // will not throw() 
{            // same as  noexcept(true) in extended signature
}            // same as deprecated throw() in ext. signature
void Student::Enroll() noexcept(false)  // may throw()
{                                       // an exception
}                                     
```

尽管如此，让我们通过查看当我们的应用程序抛出不属于函数扩展签名的异常时发生的情况，来研究为什么存在与动态异常相关的不利问题。

### 处理意外类型的动态异常

如果从 C 标准库中抛出的异常类型不是扩展函数原型中指定的类型，则将调用 `unexpected()`。你可以用`unexpected()`注册你自己的函数，就像我们在本章前面用`set_terminate()`注册了我们自己的函数一样。

您可以允许您的`AppSpecificUnexpected()`函数重新抛出始发函数应该抛出的类型的异常，但是，如果没有发生，则将调用`terminate()`。此外，如果不存在可能的匹配 catcher 来处理从原始函数正确抛出的内容 (或由您的`AppSpecificUnexpected()`重新抛出)，则将调用`terminate()`。

让我们看看如何用我们自己的功能`set_unexpected()`:

```cpp
void AppSpecificUnexpected()
{
    cout << "An unexpected type was thrown" << endl;
    // optionally re-throw the correct type, or
    // terminate() will be called.
}
int main()
{
   set_unexpected(AppSpecificUnexpected)
}
```

用`set_unexpected()`注册我们自己的函数非常简单，如前面提到的代码片段所示。

从历史上看，在函数的扩展签名中采用异常规范的一个动机是提供文档效果。也就是说，您可以通过检查其签名来查看函数可能会引发哪些异常。然后，您可以计划将该函数调用包含在 try 块中，并提供适当的捕手来处理任何潜在情况。

尽管如此，关于动态异常，有必要注意的是，编译器不会检查在函数体中抛出的异常类型*实际上*与函数扩展签名中指定的类型是否匹配。由程序员来确保它们是同步的。因此，这种不推荐使用的功能可能容易出错，并且总体而言，不如其原始意图有用。

尽管预期良好，但动态异常目前尚未使用，但大量库代码 (例如 C 标准库) 除外。由于您将不可避免地利用这些库，因此了解这些不合时宜的现象非常重要。

注

动态异常规范 (即在方法的扩展签名中指定异常类型的能力) 在 C 中已被*弃用*。这是因为编译器无法验证其使用，然后必须将其延迟到运行时。尽管仍然支持它们的使用 (许多库都有这样的规范)，但现在已弃用。

现在我们已经看到了各种异常处理检测、引发、捕获和 (希望是) 纠正方案，让我们来看看如何创建异常类的层次结构，以增加错误处理能力的复杂性。

# Utilizing exception hierarchies

创建一个类来封装与程序错误相关的详细信息似乎是一项有用的工作。实际上，C 标准库已经创建了一个这样的泛型类`exception`，为构建有用的异常类的整个层次结构提供了基础。

让我们看一下带有标准库后代的`exception`类，然后我们如何使用自己的 cassesxtend`exception`。

## 使用标准异常对象

**异常**类在 C 标准库中定义，仅通过包含`<exception>`头即可使用。`exception`类包括一个虚拟的函数，其签名如下: `virtual const char *what() const throw()`。此签名表示派生类应重新定义`what()`以返回`const char *`，并带有对错误的描述。`what()`后面的`const`关键字表示这是一个`const`成员函数; 它不会更改派生类的任何成员。扩展签名中的`throw()`表示此函数可能会抛出任何类型。签名中`throw()`的用法是过时的。

`std::exception`类是各种预先定义的 C 异常类的基类，包括`bad_alloc`、`bad_cast`、`bad_exception`、`bad_function_call`、`bad_typeid`、`bad_weak_ptr`、`logic_error`、`runtime_error`和嵌套类`ios_base::failure`。这些派生类中的许多都有后代，从而在预定义的异常层次结构中添加了其他标准异常。

如果函数抛出任何上述异常，则可以通过捕获基类类型`exception`或捕获单个派生类类型来捕获这些异常。根据您的处理程序将采取的行动，您可以决定是否希望捕获一个这样的异常，例如其广义基类类型或其特定类型。

就像标准库基于`exception`类设置了类的层次结构一样，您也可以。接下来让我们看看我们如何做到这一点!

## 创建自定义异常类

作为程序员，您可以决定建立自己的专用异常类型是有利的。每个类型都可以将有用的信息打包到一个对象中，详细说明应用程序出了什么问题。此外，您也许可以将有关如何纠正手头错误的线索 (将被抛出) 打包到对象中。只需从标准的`exception`类派生您的类。

让我们看看通过检查下一个示例的关键部分来完成此操作的难易程度，该示例可以在 GitHub 中作为完整程序找到:

[https://github.com/PacktPublishing/Demystified-Object-Oriented-Programming-with-CPP/blob/master/Chapter11/Chp11-Ex5.cpp](https://github.com/PacktPublishing/Demystified-Object-Oriented-Programming-with-CPP/blob/master/Chapter11/Chp11-Ex5.cpp)

```cpp
#include <iostream>
#include <exception>
using namespace std;
class StudentException: public exception
{
private:
    int errCode;  
    char *details;
public:           
    StudentException(const char *det, int num): errCode(num)
    {
        details = new char[strlen(det) + 1];
        strcpy(details, det);
    }   
    virtual ~StudentException() { delete details; }
    virtual const char *what() const throw()
    {   // overridden function from exception class
        return "Student Exception";
    } 
    int GetCode() const { return errCode; }
    const char *GetDetails() const { return details; }
};
// Assume Student class is as we've seen before, but with one
// additional virtual member function Graduate() 
void Student::Graduate()  // fn. may throw (StudentException)
{
   // if something goes wrong, instantiate a StudentException,
   // pack it with relevant data during construction, and then
   // throw the dereferenced pointer as a referenceable object
   throw *(new StudentException("Missing Credits", 4));
}
int main()
{
    Student s1("Alexandra", "Doone", 'G', "Miss", 3.95, 
               "C++", "231GWU");
    try
    {
        s1.Graduate();
    }
    catch (const StudentException &e)  // catch exc. by ref
    { 
        cout << e.what() << endl;
        cout << e.GetCode() << " " << e.GetDetails() << endl;
        // Grab useful info from e and try to fix the problem
        // so that the program can continue.
        // If we fix the problem, deallocate heap memory for
        // thrown exception (take addr. of a ref): delete &e; 
        // Otherwise, memory will be reclaimed upon exit()
        exit(1);  // only exit if necessary!
    }
    return 0;
}
```

让我们花几分钟时间检查上一段代码。最重要的是，请注意，我们定义了自己的异常类`StudentException`。它是来自 C标准库`exception`类的派生类。

`StudentException`类包含用于保存错误码的数据成员以及分别使用数据成员`errCode`和`details`描述错误情况的字母数字详细信息。我们有两个简单的访问功能，`StudentException``::GetCode()`和`StudentException::GetDetails()`，可以方便地检索这些值。由于这些方法不修改对象，因此它们是`const`成员函数。

我们注意到，`StudentException`构造函数初始化两个数据成员-一个通过成员初始化列表，一个在构造函数的主体中。我们还覆盖了由`exception`类引入的`virtual const char *what() const throw()`方法。请注意，`exception::what()`方法在其扩展签名中使用了不推荐使用的`throw()`规范-这是您必须对重写的方法做的事情。

接下来，让我们检查一下我们的`Student::Graduate()`方法。这个方法可能会抛出一个`StudentException`。如果必须抛出异常，我们使用`new()`分配一个，用诊断数据构造它，然后`throw`从这个函数中取消引用的指针 (这样我们就抛出了一个可引用的对象，而不是指向对象的指针)。请注意，抛出的对象在此方法中没有本地标识符-没有必要，因为在发生`throw`之后，任何这样的本地变量名称都将很快从堆栈中弹出。

在我们的`main()`函数中，我们将对`s1.Graduate()`的调用包装在 try 块中，其后是接受对`StudentException`的引用 (`&`) 的 catch 块，我们将其视为`const`。在这里，我们首先调用重写的`what()`方法，然后从异常`e`中打印出诊断详细信息。理想情况下，我们将使用此信息来尝试纠正手头的错误，如果确实需要，请退出应用程序。

让我们看一下上述程序的输出:

```cpp
Student Exception
4 Missing Credits
```

尽管创建自定义异常类的最常用方法是从标准`exception`类中派生一个类，但也可能希望使用另一种技术，即嵌入式异常类。

### 创建嵌套异常类

作为替代的实现，可以通过在公共访问区域中添加特定外部类的嵌套类定义，将异常处理嵌入到类中。内部类将表示自定义的异常类。

可以创建嵌套的用户定义类型的对象，并将其扔给预期此类类型的捕手。这些嵌套类被内置到外部类的公共访问区域中，从而使它们易于用于派生类的使用和专业化。通常，外部类中内置的异常类必须是公共的，以便可以在外部类的范围之外 (即在主要外部实例存在的范围内) 捕获和处理嵌套类型的实例。

让我们通过检查关键代码段来看看异常类的替代实现，这些代码可以在我们的 GitHub 中作为完整程序找到:

[https://github.com/PacktPublishing/Demystified-Object-Oriented-Programming-with-CPP/blob/master/Chapter11/Chp11-Ex6.cpp](https://github.com/PacktPublishing/Demystified-Object-Oriented-Programming-with-CPP/blob/master/Chapter11/Chp11-Ex6.cpp)

```cpp
// Assume Student class is as before, but with the addition 
// of a nested exception class. All headers are as usual.
class Student: public Person
{
private:  // assume usual data members
public:   // usual constructors, destructor, and methods
    virtual void Graduate();
    class StudentException   // nested exception class
    {
    private:
        int number;
    public:
        StudentException(int num): number(num) { }
        ~StudentException() { }
        int GetNum() const { return number; }
    };
};
void Student::Graduate()
{   // assume we determine an error and wish to throw
    // the nested exception type
    throw *(new StudentException(5));
}
int main()
{
    Student s1("Ling", "Mau", 'I', "Ms.", 3.1, "C++", "55UD");
    try
    {
        s1.Graduate();
    }
    catch (const Student::StudentException &err)
    {
        cout << "Error: " << err.GetNum() << endl;
        // If you correct err and continue with program, be
        // sure to delete heap mem for err: delete &err;
        exit(1);  // Otherwise, heap memory for err will be 
    }             // reclaimed upon exit()
    cout << "Moving onward with remainder of code." << endl;
    return 0;
}
```

在前面的代码片段中，我们扩展了我们的`Student`class，以包含一个名为`StudentException`的私有嵌套类。尽管显示的类过于简化，但理想情况下，嵌套类应该定义一种方法来对所讨论的错误进行分类以及收集任何有用的诊断信息。

在我们的`main()`函数中，我们实例化了一个`Student`，即`s1`。在 try 块中，我们调用`s1.Graduate();`。我们的`Student::Graduate()`方法可能会检查`Student`是否已满足毕业要求，如果没有，则抛出嵌套类类型`Student::StudentException`的异常 (它会根据需要实例化)。

请注意，我们对应的`catch`块使用范围解析来指定`err`的内部类类型，即引用的对象 (即`const Student::StudentException &err`)。尽管理想情况下，我们希望纠正处理程序中的程序错误，但如果不能，我们只需打印一条消息并`exit()`。

让我们看一下上述程序的 output:

```cpp
Error: 5
```

了解如何创建我们自己的异常类 (作为嵌套类或派生自`std::exception`) 是有用的。我们可能还希望创建特定于应用程序的异常层次结构。让我们继续前进，看看如何做到这一点。

## 创建用户定义的异常类型的层次结构

应用程序可能希望定义一系列支持异常处理以引发特定错误的类，并且希望还提供一种方法来收集错误的诊断，以便可以在代码的适当部分中解决错误。

您可能希望为自己的异常类创建一个从标准库`exception`派生的子层次结构。一定要使用公共继承。当使用这些类时，您将实例化您想要的异常类型的对象 (用有价值的诊断信息填充它)，然后抛出该对象。请记住，您将希望新分配的对象存在于堆上，以便在函数返回时不会将其从堆栈中弹出 (因此，请使用`new`分配它)。只需在抛出该对象之前取消引用该对象，以便可以将其捕获为对该对象的引用，这是标准做法。

此外，如果创建异常类型的层次结构，则捕获器可以捕获特定的派生类类型或更通用的基类类型。该选项是您的，具体取决于您计划如何处理异常。但是，请记住，如果您同时拥有基类和派生类类型的捕手，请首先放置派生类类型-否则您抛出的对象将首先与基类类型捕手匹配，而没有意识到更合适的派生类匹配是可用的。

我们现在已经看到了 C 标准库异常类的层次结构，以及如何创建和利用自己的异常类。现在让我们简要回顾一下我们在本章中了解到的异常功能，然后再进入下一章。

# 总结

在本章中，我们已经开始扩展我们的 C 编程库，超越 OOP 语言功能，以包括使我们能够编写更强大的程序的功能。用户代码本质上不可避免地容易出错; 使用语言支持的异常处理可以帮助我们实现更少的错误和更可靠的代码。

我们已经看到了如何使用`try`，`throw`和`catch`来使用核心异常处理功能。我们已经看到了这些关键字的各种用途-向外部处理程序抛出异常，使用各种类型的处理程序，并在单个 try 块中选择性地将程序元素组合在一起。我们已经看到了如何用`set_terminate()`和`set_unexpected()`注册自己的功能。我们已经看到了如何利用现有的 C 标准库`exception`层次结构。我们还探索了定义自己的异常类来扩展此层次结构。

通过探索异常处理机制，我们为 C 技能添加了关键功能。我们现在准备前进到[*第 12 章*](12.html#_idTextAnchor453)，*朋友和运算符重载*，这样我们就可以继续用有用的语言功能扩展我们的 C 编程库，这将使成为我们更好的程序员。让我们继续前进!

# 问题

1.  Add exception handling to your previous `Student` / `University` exercise from [*Chapter 10*](10.html#_idTextAnchor386), *Implementing Association, Aggregation, and Composition*:

    答: 如果`Student`尝试注册超过`MAX`定义的每个`Student`的允许课程数量，则引发`TooFullSchedule`异常。此类可能源自标准库`exception`类。

    b.如果`Student`尝试注册已经满的`Course`，则`Course::AddStudent(Student *)`方法会引发`CourseFull`异常。此类可能源自标准库`exception`类。

    c.在`Student`/`University`应用程序中有许多其他领域可以利用异常处理。确定哪些区域应采用简单的错误检查，哪些区域值得进行异常处理。